<sdf version='1.7'>
  <world name='default'>
    <light name='sun' type='directional'>
      <cast_shadows>1</cast_shadows>
      <pose>0 0 10 0 -0 0</pose>
      <diffuse>0.8 0.8 0.8 1</diffuse>
      <specular>0.2 0.2 0.2 1</specular>
      <attenuation>
        <range>1000</range>
        <constant>0.9</constant>
        <linear>0.01</linear>
        <quadratic>0.001</quadratic>
      </attenuation>
      <direction>-0.5 0.1 -0.9</direction>
      <spot>
        <inner_angle>0</inner_angle>
        <outer_angle>0</outer_angle>
        <falloff>0</falloff>
      </spot>
    </light>
    <model name='ground_plane'>
      <static>1</static>
      <link name='link'>
        <collision name='collision'>
          <geometry>
            <plane>
              <normal>0 0 1</normal>
              <size>100 100</size>
            </plane>
          </geometry>
          <surface>
            <friction>
              <ode>
                <mu>100</mu>
                <mu2>50</mu2>
              </ode>
              <torsional>
                <ode/>
              </torsional>
            </friction>
            <contact>
              <ode/>
            </contact>
            <bounce/>
          </surface>
          <max_contacts>10</max_contacts>
        </collision>
        <visual name='visual'>
          <cast_shadows>0</cast_shadows>
          <geometry>
            <plane>
              <normal>0 0 1</normal>
              <size>100 100</size>
            </plane>
          </geometry>
          <material>
            <script>
              <uri>file://media/materials/scripts/gazebo.material</uri>
              <name>Gazebo/Grey</name>
            </script>
          </material>
        </visual>
        <self_collide>0</self_collide>
        <enable_wind>0</enable_wind>
        <kinematic>0</kinematic>
      </link>
    </model>
    <gravity>0 0 -9.8</gravity>
    <magnetic_field>6e-06 2.3e-05 -4.2e-05</magnetic_field>
    <atmosphere type='adiabatic'/>
    <physics type='ode'>
      <max_step_size>0.001</max_step_size>
      <real_time_factor>1</real_time_factor>
      <real_time_update_rate>1000</real_time_update_rate>
    </physics>
    <scene>
      <ambient>0.4 0.4 0.4 1</ambient>
      <background>0.7 0.7 0.7 1</background>
      <shadows>1</shadows>
    </scene>
    <wind/>
    <spherical_coordinates>
      <surface_model>EARTH_WGS84</surface_model>
      <latitude_deg>0</latitude_deg>
      <longitude_deg>0</longitude_deg>
      <elevation>0</elevation>
      <heading_deg>0</heading_deg>
    </spherical_coordinates>
    <state world_name='default'>
      <sim_time>1019 91000000</sim_time>
      <real_time>54 983673435</real_time>
      <wall_time>1705855195 765864441</wall_time>
      <iterations>53688</iterations>
      <model name='amr'>
        <pose>3.60001 -3.7e-05 -0.007537 -1e-06 1e-06 -2e-06</pose>
        <scale>1 1 1</scale>
        <link name='base_footprint'>
          <pose>3.60001 -3.7e-05 -0.007537 -1e-06 1e-06 -2e-06</pose>
          <velocity>0 3.8e-05 -0.000138 -1.1e-05 -1e-06 -0</velocity>
          <acceleration>-0 -5e-05 -0.000105 2.7e-05 -2e-06 -0</acceleration>
          <wrench>-1.7e-05 -0.003991 -0.008331 0 -0 0</wrench>
        </link>
        <link name='bl_caster_1_wheel_link'>
          <pose>3.20001 0.258947 0.029997 0.000182 0.000298 -0.000295</pose>
          <velocity>0 -0.000206 -0.000186 0.005144 1.2e-05 -4e-06</velocity>
          <acceleration>0 -0.000197 -0.000161 0.00493 1e-06 -2e-06</acceleration>
          <wrench>0 -9.9e-05 -8.1e-05 0 -0 0</wrench>
        </link>
        <link name='bl_caster_2_wheel_link'>
          <pose>3.2 0.23497 0.029994 -0.000563 0.000121 -0.000295</pose>
          <velocity>0 0.000317 -0.000428 -0.007926 1e-05 -4e-06</velocity>
          <acceleration>0 0.000288 -0.000243 -0.007193 2e-06 -1e-06</acceleration>
          <wrench>0 0.000144 -0.000121 0 -0 0</wrench>
        </link>
        <link name='bl_caster_rotation_link'>
          <pose>3.20001 0.246967 0.079996 0.000135 1e-06 -0.000295</pose>
          <velocity>0 9.5e-05 -0.000163 0.003899 -1e-05 -3e-06</velocity>
          <acceleration>-0 1.9e-05 -0.00012 0.003449 -1e-05 -1e-06</acceleration>
          <wrench>-0 4e-06 -2.4e-05 0 -0 0</wrench>
        </link>
        <link name='br_caster_1_wheel_link'>
          <pose>3.20002 -0.235053 0.029997 0.000184 0.00052 -0.001003</pose>
          <velocity>1e-06 -0.000209 -0.00019 0.005233 1.7e-05 -2.1e-05</velocity>
          <acceleration>-0 -0.000205 -0.000169 0.005131 -5e-06 0</acceleration>
          <wrench>-0 -0.000103 -8.4e-05 0 -0 0</wrench>
        </link>
        <link name='br_caster_2_wheel_link'>
          <pose>3.19999 -0.25903 0.029994 -0.000563 -8.3e-05 -0.001004</pose>
          <velocity>1e-06 0.000319 -0.000442 -0.007971 2.9e-05 -2.1e-05</velocity>
          <acceleration>1e-06 0.000303 -0.000269 -0.00756 2.6e-05 -1e-06</acceleration>
          <wrench>0 0.000151 -0.000135 0 -0 0</wrench>
        </link>
        <link name='br_caster_rotation_link'>
          <pose>3.20001 -0.247033 0.079996 0.000136 1e-06 -0.001004</pose>
          <velocity>1e-06 9.5e-05 -0.000167 0.003978 -1e-06 -2.2e-05</velocity>
          <acceleration>0 2.2e-05 -0.000129 0.003599 4e-06 -3e-06</acceleration>
          <wrench>0 4e-06 -2.6e-05 0 -0 0</wrench>
        </link>
        <link name='fl_caster_1_wheel_link'>
          <pose>4 0.258945 0.029997 0.000182 0.000121 0.000227</pose>
          <velocity>0 -0.000206 -0.000187 0.005156 1e-06 5e-06</velocity>
          <acceleration>-0 -0.000197 -0.000162 0.004926 -6e-06 -1e-06</acceleration>
          <wrench>-0 -9.8e-05 -8.1e-05 0 -0 0</wrench>
        </link>
        <link name='fl_caster_2_wheel_link'>
          <pose>4.00001 0.234969 0.029994 -0.000563 0.000258 0.000227</pose>
          <velocity>-0 0.000318 -0.000429 -0.007962 -3e-06 5e-06</velocity>
          <acceleration>-1e-06 0.000288 -0.000243 -0.007191 -1.6e-05 0</acceleration>
          <wrench>-0 0.000144 -0.000121 0 -0 0</wrench>
        </link>
        <link name='fl_caster_rotation_link'>
          <pose>4.00001 0.246965 0.079996 0.000135 -1e-06 0.000227</pose>
          <velocity>0 9.5e-05 -0.000163 0.003903 -1e-06 6e-06</velocity>
          <acceleration>-0 1.9e-05 -0.00012 0.003444 -4e-06 0</acceleration>
          <wrench>-0 4e-06 -2.4e-05 0 -0 0</wrench>
        </link>
        <link name='fr_caster_1_wheel_link'>
          <pose>4 -0.235055 0.029997 0.000184 8.7e-05 0.000268</pose>
          <velocity>-0 -0.00021 -0.000191 0.005249 -2e-06 5e-06</velocity>
          <acceleration>-0 -0.000205 -0.000169 0.005125 -1e-05 0</acceleration>
          <wrench>-0 -0.000102 -8.4e-05 0 -0 0</wrench>
        </link>
        <link name='fr_caster_2_wheel_link'>
          <pose>4.00001 -0.259031 0.029994 -0.000564 0.000248 0.000267</pose>
          <velocity>-0 0.00032 -0.000443 -0.008015 -4e-06 5e-06</velocity>
          <acceleration>-1e-06 0.000302 -0.000269 -0.007557 -1.7e-05 0</acceleration>
          <wrench>-0 0.000151 -0.000135 0 -0 0</wrench>
        </link>
        <link name='fr_caster_rotation_link'>
          <pose>4.00001 -0.247035 0.079996 0.000136 -0 0.000268</pose>
          <velocity>0 9.5e-05 -0.000167 0.003985 4e-06 5e-06</velocity>
          <acceleration>-0 2.2e-05 -0.000129 0.003593 -0 1e-06</acceleration>
          <wrench>-0 4e-06 -2.6e-05 0 -0 0</wrench>
        </link>
        <link name='left_wheel_link'>
          <pose>3.60001 0.266961 0.08246 -6.1e-05 8.7e-05 -2e-06</pose>
          <velocity>0 3.4e-05 -0.000155 -4.7e-05 1e-06 0</velocity>
          <acceleration>-0 -6e-05 -0.000169 0.000134 -4e-06 0</acceleration>
          <wrench>-0 -6e-05 -0.000169 0 -0 0</wrench>
        </link>
        <link name='right_wheel_link'>
          <pose>3.60001 -0.267038 0.08246 -3.7e-05 7.6e-05 -2e-06</pose>
          <velocity>0 3e-05 -0.000165 -8.5e-05 1e-06 -0</velocity>
          <acceleration>-0 -6.5e-05 -0.000195 0.000434 -5e-06 0</acceleration>
          <wrench>-0 -6.5e-05 -0.000195 0 -0 0</wrench>
        </link>
      </model>
      <model name='ground_plane'>
        <pose>0 0 0 0 -0 0</pose>
        <scale>1 1 1</scale>
        <link name='link'>
          <pose>0 0 0 0 -0 0</pose>
          <velocity>0 0 0 0 -0 0</velocity>
          <acceleration>0 0 0 0 -0 0</acceleration>
          <wrench>0 0 0 0 -0 0</wrench>
        </link>
      </model>
      <model name='vl_marker'>
        <pose>4.54 0 0.0015 0 0 -1.5708</pose>
        <scale>1 1 1</scale>
        <link name='body'>
          <pose>4.54 0 0.0015 0 -0 -1.5708</pose>
          <velocity>0 0 0 0 -0 0</velocity>
          <acceleration>0 0 0 0 -0 0</acceleration>
          <wrench>0 0 0 0 -0 0</wrench>
        </link>
      </model>
      <light name='sun'>
        <pose>0 0 10 0 -0 0</pose>
      </light>
    </state>
    <gui fullscreen='0'>
      <camera name='user_camera'>
        <pose>5.81311 -0.046716 16.2112 -1e-06 1.5418 1.54339</pose>
        <view_controller>orbit</view_controller>
        <projection_type>perspective</projection_type>
      </camera>
    </gui>
    <model name='vl_marker'>
      <link name='body'>
        <pose>0 0 0 0 -0 0</pose>
        <self_collide>0</self_collide>
        <enable_wind>0</enable_wind>
        <kinematic>0</kinematic>
        <visual name='visual'>
          <geometry>
            <mesh>
              <uri>model://vl_marker/vl_marker.STL</uri>
            </mesh>
          </geometry>
          <material>
            <shader type='pixel'/>
          </material>
          <pose>0 0 0 0 -0 0</pose>
          <transparency>0</transparency>
          <cast_shadows>1</cast_shadows>
          <origin xyz='0.0 0.0 0.0' rpy='0 0 0'/>
        </visual>
        <collision name='collision'>
          <laser_retro>0</laser_retro>
          <max_contacts>10</max_contacts>
          <pose>0 0 0 0 -0 0</pose>
          <geometry>
            <mesh>
              <uri>model://vl_marker/vl_marker.STL</uri>
              <scale>1 1 1</scale>
            </mesh>
          </geometry>
          <surface>
            <friction>
              <ode>
                <mu>1</mu>
                <mu2>1</mu2>
                <fdir1>0 0 0</fdir1>
                <slip1>0</slip1>
                <slip2>0</slip2>
              </ode>
              <torsional>
                <coefficient>1</coefficient>
                <patch_radius>0</patch_radius>
                <surface_radius>0</surface_radius>
                <use_patch_radius>1</use_patch_radius>
                <ode>
                  <slip>0</slip>
                </ode>
              </torsional>
            </friction>
            <bounce>
              <restitution_coefficient>0</restitution_coefficient>
              <threshold>1e+06</threshold>
            </bounce>
            <contact>
              <collide_without_contact>0</collide_without_contact>
              <collide_without_contact_bitmask>1</collide_without_contact_bitmask>
              <collide_bitmask>1</collide_bitmask>
              <ode>
                <soft_cfm>0</soft_cfm>
                <soft_erp>0.2</soft_erp>
                <kp>1e+13</kp>
                <kd>1</kd>
                <max_vel>0.01</max_vel>
                <min_depth>0</min_depth>
              </ode>
              <bullet>
                <split_impulse>1</split_impulse>
                <split_impulse_penetration_threshold>-0.01</split_impulse_penetration_threshold>
                <soft_cfm>0</soft_cfm>
                <soft_erp>0.2</soft_erp>
                <kp>1e+13</kp>
                <kd>1</kd>
              </bullet>
            </contact>
          </surface>
        </collision>
      </link>
      <static>1</static>
      <allow_auto_disable>1</allow_auto_disable>
      <pose>0.229582 -0.067605 0 0 -0 0</pose>
    </model>
    <model name='amr'>
      <link name='base_footprint'>
        <inertial>
          <pose>0 0 0.002599 0 -0 0</pose>
          <mass>79.4</mass>
          <inertia>
            <ixx>6.24265</ixx>
            <ixy>-9.76561e-16</ixy>
            <ixz>0</ixz>
            <iyy>3.17928</iyy>
            <iyz>0</iyz>
            <izz>8.60809</izz>
          </inertia>
        </inertial>
        <collision name='base_footprint_fixed_joint_lump__base_link_collision'>
          <pose>0 0 0 0 -0 1.5708</pose>
          <geometry>
            <mesh>
              <scale>1 1 1</scale>
              <uri>/home/leanhchien/temas_work/temas_ws/src/amr_simulation/amr_description/meshes/base.STL</uri>
            </mesh>
          </geometry>
          <surface>
            <contact>
              <ode/>
            </contact>
            <friction>
              <ode/>
              <torsional>
                <ode/>
              </torsional>
            </friction>
            <bounce/>
          </surface>
          <max_contacts>10</max_contacts>
        </collision>
        <collision name='base_footprint_fixed_joint_lump__back_laser_link_collision_1'>
          <pose>-0.4 0 0.086 1.5708 -0 3.14159</pose>
          <geometry>
            <mesh>
              <scale>1 1 1</scale>
              <uri>/home/leanhchien/temas_work/temas_ws/src/amr_simulation/amr_description/meshes/lidar.STL</uri>
            </mesh>
          </geometry>
          <surface>
            <contact>
              <ode/>
            </contact>
            <friction>
              <ode/>
              <torsional>
                <ode/>
              </torsional>
            </friction>
            <bounce/>
          </surface>
          <max_contacts>10</max_contacts>
        </collision>
        <collision name='base_footprint_fixed_joint_lump__front_laser_link_collision_2'>
          <pose>0.4 0 0.086 1.5708 -0 0</pose>
          <geometry>
            <mesh>
              <scale>1 1 1</scale>
              <uri>/home/leanhchien/temas_work/temas_ws/src/amr_simulation/amr_description/meshes/lidar.STL</uri>
            </mesh>
          </geometry>
          <surface>
            <contact>
              <ode/>
            </contact>
            <friction>
              <ode/>
              <torsional>
                <ode/>
              </torsional>
            </friction>
            <bounce/>
          </surface>
          <max_contacts>10</max_contacts>
        </collision>
        <visual name='base_footprint_fixed_joint_lump__base_link_visual'>
          <pose>0 0 0 0 -0 1.5708</pose>
          <geometry>
            <mesh>
              <scale>1 1 1</scale>
              <uri>/home/leanhchien/temas_work/temas_ws/src/amr_simulation/amr_description/meshes/base.STL</uri>
            </mesh>
          </geometry>
          <material>
            <script>
              <name>Gazebo/White</name>
              <uri>file://media/materials/scripts/gazebo.material</uri>
            </script>
          </material>
        </visual>
        <visual name='base_footprint_fixed_joint_lump__back_laser_link_visual_1'>
          <pose>-0.4 0 0.086 1.5708 -0 3.14159</pose>
          <geometry>
            <mesh>
              <scale>1 1 1</scale>
              <uri>/home/leanhchien/temas_work/temas_ws/src/amr_simulation/amr_description/meshes/lidar.STL</uri>
            </mesh>
          </geometry>
          <material>
            <script>
              <name>Gazebo/FlatBlack</name>
              <uri>file://media/materials/scripts/gazebo.material</uri>
            </script>
          </material>
        </visual>
        <visual name='base_footprint_fixed_joint_lump__front_laser_link_visual_2'>
          <pose>0.4 0 0.086 1.5708 -0 0</pose>
          <geometry>
            <mesh>
              <scale>1 1 1</scale>
              <uri>/home/leanhchien/temas_work/temas_ws/src/amr_simulation/amr_description/meshes/lidar.STL</uri>
            </mesh>
          </geometry>
          <material>
            <script>
              <name>Gazebo/FlatBlack</name>
              <uri>file://media/materials/scripts/gazebo.material</uri>
            </script>
          </material>
        </visual>
        <sensor name='back_laser_link' type='ray'>
          <visualize>0</visualize>
          <update_rate>12.5</update_rate>
          <ray>
            <scan>
              <horizontal>
                <samples>720</samples>
                <resolution>1</resolution>
                <min_angle>-1.5708</min_angle>
                <max_angle>1.5708</max_angle>
              </horizontal>
              <vertical>
                <samples>1</samples>
                <min_angle>0</min_angle>
                <max_angle>0</max_angle>
              </vertical>
            </scan>
            <range>
              <min>0.05</min>
              <max>30</max>
              <resolution>0.01</resolution>
            </range>
            <noise>
              <type>gaussian</type>
              <mean>0.02</mean>
              <stddev>0.001</stddev>
            </noise>
          </ray>
          <plugin name='gazebo_ros_back_laser_link_controller' filename='libgazebo_ros_laser.so'>
            <frameName>back_laser_link</frameName>
            <topicName>back_scan</topicName>
            <robotNamespace>/</robotNamespace>
          </plugin>
          <pose>-0.4 0 0.1435 0 -0 3.14159</pose>
        </sensor>
        <sensor name='front_laser_link' type='ray'>
          <visualize>0</visualize>
          <update_rate>12.5</update_rate>
          <ray>
            <scan>
              <horizontal>
                <samples>720</samples>
                <resolution>1</resolution>
                <min_angle>-1.5708</min_angle>
                <max_angle>1.5708</max_angle>
              </horizontal>
              <vertical>
                <samples>1</samples>
                <min_angle>0</min_angle>
                <max_angle>0</max_angle>
              </vertical>
            </scan>
            <range>
              <min>0.05</min>
              <max>30</max>
              <resolution>0.01</resolution>
            </range>
            <noise>
              <type>gaussian</type>
              <mean>0.02</mean>
              <stddev>0.001</stddev>
            </noise>
          </ray>
          <plugin name='gazebo_ros_front_laser_link_controller' filename='libgazebo_ros_laser.so'>
            <frameName>front_laser_link</frameName>
            <topicName>front_scan</topicName>
            <robotNamespace>/</robotNamespace>
          </plugin>
          <pose>0.4 0 0.1435 0 -0 0</pose>
        </sensor>
        <self_collide>0</self_collide>
        <enable_wind>0</enable_wind>
        <kinematic>0</kinematic>
      </link>
      <joint name='bl_caster_rotation_joint' type='revolute'>
        <pose relative_to='base_footprint'>-0.4 0.247 0.0875 0 -0 0</pose>
        <parent>base_footprint</parent>
        <child>bl_caster_rotation_link</child>
        <axis>
          <xyz>0 0 1</xyz>
          <limit>
            <lower>-1e+16</lower>
            <upper>1e+16</upper>
          </limit>
          <dynamics>
            <damping>0.01</damping>
            <friction>0</friction>
            <spring_reference>0</spring_reference>
            <spring_stiffness>0</spring_stiffness>
          </dynamics>
        </axis>
      </joint>
      <link name='bl_caster_rotation_link'>
        <pose relative_to='bl_caster_rotation_joint'>0 0 0 0 -0 0</pose>
        <inertial>
          <pose>0 0 0 0 -0 0</pose>
          <mass>0.2</mass>
          <inertia>
            <ixx>7e-05</ixx>
            <ixy>0</ixy>
            <ixz>0</ixz>
            <iyy>3.9e-05</iyy>
            <iyz>0</iyz>
            <izz>9.24e-05</izz>
          </inertia>
        </inertial>
        <collision name='bl_caster_rotation_link_collision'>
          <pose>0 0 0 1.5708 -0 1.5708</pose>
          <geometry>
            <mesh>
              <scale>1 1 1</scale>
              <uri>/home/leanhchien/temas_work/temas_ws/src/amr_simulation/amr_description/meshes/caster_base.STL</uri>
            </mesh>
          </geometry>
          <surface>
            <contact>
              <ode/>
            </contact>
            <friction>
              <ode/>
              <torsional>
                <ode/>
              </torsional>
            </friction>
            <bounce/>
          </surface>
          <max_contacts>10</max_contacts>
        </collision>
        <visual name='bl_caster_rotation_link_visual'>
          <pose>0 0 0 1.5708 -0 1.5708</pose>
          <geometry>
            <mesh>
              <scale>1 1 1</scale>
              <uri>/home/leanhchien/temas_work/temas_ws/src/amr_simulation/amr_description/meshes/caster_base.STL</uri>
            </mesh>
          </geometry>
          <material>
            <script>
              <name>Gazebo/Grey</name>
              <uri>file://media/materials/scripts/gazebo.material</uri>
            </script>
          </material>
        </visual>
        <self_collide>0</self_collide>
        <enable_wind>0</enable_wind>
        <kinematic>0</kinematic>
      </link>
      <joint name='bl_caster_wheel_1_joint' type='revolute'>
        <pose relative_to='bl_caster_rotation_link'>0 0.012 -0.05 0 -0 0</pose>
        <parent>bl_caster_rotation_link</parent>
        <child>bl_caster_1_wheel_link</child>
        <axis>
          <xyz>0 1 0</xyz>
          <limit>
            <lower>-1e+16</lower>
            <upper>1e+16</upper>
          </limit>
          <dynamics>
            <spring_reference>0</spring_reference>
            <spring_stiffness>0</spring_stiffness>
          </dynamics>
        </axis>
      </joint>
      <link name='bl_caster_1_wheel_link'>
        <pose relative_to='bl_caster_wheel_1_joint'>0 0 0 0 -0 0</pose>
        <inertial>
          <pose>0 0 0 1.5708 -0 0</pose>
          <mass>0.5</mass>
          <inertia>
            <ixx>0.000216667</ixx>
            <ixy>0</ixy>
            <ixz>0</ixz>
            <iyy>0.000216667</iyy>
            <iyz>0</iyz>
            <izz>0.0004</izz>
          </inertia>
        </inertial>
        <collision name='bl_caster_1_wheel_link_collision'>
          <pose>0 0 0 1.5708 -0 0</pose>
          <geometry>
            <cylinder>
              <length>0.02</length>
              <radius>0.04</radius>
            </cylinder>
          </geometry>
          <surface>
            <contact>
              <ode>
                <kp>1e+07</kp>
                <kd>1</kd>
                <min_depth>0.01</min_depth>
              </ode>
            </contact>
            <friction>
              <ode>
                <mu>0.1</mu>
                <mu2>0.1</mu2>
              </ode>
              <torsional>
                <ode/>
              </torsional>
            </friction>
            <bounce/>
          </surface>
          <max_contacts>10</max_contacts>
        </collision>
        <visual name='bl_caster_1_wheel_link_visual'>
          <pose>0 0 0 1.5708 -0 0</pose>
          <geometry>
            <cylinder>
              <length>0.02</length>
              <radius>0.04</radius>
            </cylinder>
          </geometry>
          <material>
            <script>
              <name>Gazebo/FlatBlack</name>
              <uri>file://media/materials/scripts/gazebo.material</uri>
            </script>
          </material>
        </visual>
        <self_collide>0</self_collide>
        <enable_wind>0</enable_wind>
        <kinematic>0</kinematic>
      </link>
      <joint name='bl_caster_wheel_2_joint' type='revolute'>
        <pose relative_to='bl_caster_rotation_link'>0 -0.012 -0.05 0 -0 0</pose>
        <parent>bl_caster_rotation_link</parent>
        <child>bl_caster_2_wheel_link</child>
        <axis>
          <xyz>0 1 0</xyz>
          <limit>
            <lower>-1e+16</lower>
            <upper>1e+16</upper>
          </limit>
          <dynamics>
            <spring_reference>0</spring_reference>
            <spring_stiffness>0</spring_stiffness>
          </dynamics>
        </axis>
      </joint>
      <link name='bl_caster_2_wheel_link'>
        <pose relative_to='bl_caster_wheel_2_joint'>0 0 0 0 -0 0</pose>
        <inertial>
          <pose>0 0 0 1.5708 -0 0</pose>
          <mass>0.5</mass>
          <inertia>
            <ixx>0.000216667</ixx>
            <ixy>0</ixy>
            <ixz>0</ixz>
            <iyy>0.000216667</iyy>
            <iyz>0</iyz>
            <izz>0.0004</izz>
          </inertia>
        </inertial>
        <collision name='bl_caster_2_wheel_link_collision'>
          <pose>0 0 0 1.5708 -0 0</pose>
          <geometry>
            <cylinder>
              <length>0.02</length>
              <radius>0.04</radius>
            </cylinder>
          </geometry>
          <surface>
            <contact>
              <ode>
                <kp>1e+07</kp>
                <kd>1</kd>
                <min_depth>0.01</min_depth>
              </ode>
            </contact>
            <friction>
              <ode>
                <mu>0.1</mu>
                <mu2>0.1</mu2>
              </ode>
              <torsional>
                <ode/>
              </torsional>
            </friction>
            <bounce/>
          </surface>
          <max_contacts>10</max_contacts>
        </collision>
        <visual name='bl_caster_2_wheel_link_visual'>
          <pose>0 0 0 1.5708 -0 0</pose>
          <geometry>
            <cylinder>
              <length>0.02</length>
              <radius>0.04</radius>
            </cylinder>
          </geometry>
          <material>
            <script>
              <name>Gazebo/FlatBlack</name>
              <uri>file://media/materials/scripts/gazebo.material</uri>
            </script>
          </material>
        </visual>
        <self_collide>0</self_collide>
        <enable_wind>0</enable_wind>
        <kinematic>0</kinematic>
      </link>
      <joint name='br_caster_rotation_joint' type='revolute'>
        <pose relative_to='base_footprint'>-0.4 -0.247 0.0875 0 -0 0</pose>
        <parent>base_footprint</parent>
        <child>br_caster_rotation_link</child>
        <axis>
          <xyz>0 0 1</xyz>
          <limit>
            <lower>-1e+16</lower>
            <upper>1e+16</upper>
          </limit>
          <dynamics>
            <damping>0.01</damping>
            <friction>0</friction>
            <spring_reference>0</spring_reference>
            <spring_stiffness>0</spring_stiffness>
          </dynamics>
        </axis>
      </joint>
      <link name='br_caster_rotation_link'>
        <pose relative_to='br_caster_rotation_joint'>0 0 0 0 -0 0</pose>
        <inertial>
          <pose>0 0 0 0 -0 0</pose>
          <mass>0.2</mass>
          <inertia>
            <ixx>7e-05</ixx>
            <ixy>0</ixy>
            <ixz>0</ixz>
            <iyy>3.9e-05</iyy>
            <iyz>0</iyz>
            <izz>9.24e-05</izz>
          </inertia>
        </inertial>
        <collision name='br_caster_rotation_link_collision'>
          <pose>0 0 0 1.5708 -0 1.5708</pose>
          <geometry>
            <mesh>
              <scale>1 1 1</scale>
              <uri>/home/leanhchien/temas_work/temas_ws/src/amr_simulation/amr_description/meshes/caster_base.STL</uri>
            </mesh>
          </geometry>
          <surface>
            <contact>
              <ode/>
            </contact>
            <friction>
              <ode/>
              <torsional>
                <ode/>
              </torsional>
            </friction>
            <bounce/>
          </surface>
          <max_contacts>10</max_contacts>
        </collision>
        <visual name='br_caster_rotation_link_visual'>
          <pose>0 0 0 1.5708 -0 1.5708</pose>
          <geometry>
            <mesh>
              <scale>1 1 1</scale>
              <uri>/home/leanhchien/temas_work/temas_ws/src/amr_simulation/amr_description/meshes/caster_base.STL</uri>
            </mesh>
          </geometry>
          <material>
            <script>
              <name>Gazebo/Grey</name>
              <uri>file://media/materials/scripts/gazebo.material</uri>
            </script>
          </material>
        </visual>
        <self_collide>0</self_collide>
        <enable_wind>0</enable_wind>
        <kinematic>0</kinematic>
      </link>
      <joint name='br_caster_wheel_1_joint' type='revolute'>
        <pose relative_to='br_caster_rotation_link'>0 0.012 -0.05 0 -0 0</pose>
        <parent>br_caster_rotation_link</parent>
        <child>br_caster_1_wheel_link</child>
        <axis>
          <xyz>0 1 0</xyz>
          <limit>
            <lower>-1e+16</lower>
            <upper>1e+16</upper>
          </limit>
          <dynamics>
            <spring_reference>0</spring_reference>
            <spring_stiffness>0</spring_stiffness>
          </dynamics>
        </axis>
      </joint>
      <link name='br_caster_1_wheel_link'>
        <pose relative_to='br_caster_wheel_1_joint'>0 0 0 0 -0 0</pose>
        <inertial>
          <pose>0 0 0 1.5708 -0 0</pose>
          <mass>0.5</mass>
          <inertia>
            <ixx>0.000216667</ixx>
            <ixy>0</ixy>
            <ixz>0</ixz>
            <iyy>0.000216667</iyy>
            <iyz>0</iyz>
            <izz>0.0004</izz>
          </inertia>
        </inertial>
        <collision name='br_caster_1_wheel_link_collision'>
          <pose>0 0 0 1.5708 -0 0</pose>
          <geometry>
            <cylinder>
              <length>0.02</length>
              <radius>0.04</radius>
            </cylinder>
          </geometry>
          <surface>
            <contact>
              <ode>
                <kp>1e+07</kp>
                <kd>1</kd>
                <min_depth>0.01</min_depth>
              </ode>
            </contact>
            <friction>
              <ode>
                <mu>0.1</mu>
                <mu2>0.1</mu2>
              </ode>
              <torsional>
                <ode/>
              </torsional>
            </friction>
            <bounce/>
          </surface>
          <max_contacts>10</max_contacts>
        </collision>
        <visual name='br_caster_1_wheel_link_visual'>
          <pose>0 0 0 1.5708 -0 0</pose>
          <geometry>
            <cylinder>
              <length>0.02</length>
              <radius>0.04</radius>
            </cylinder>
          </geometry>
          <material>
            <script>
              <name>Gazebo/FlatBlack</name>
              <uri>file://media/materials/scripts/gazebo.material</uri>
            </script>
          </material>
        </visual>
        <self_collide>0</self_collide>
        <enable_wind>0</enable_wind>
        <kinematic>0</kinematic>
      </link>
      <joint name='br_caster_wheel_2_joint' type='revolute'>
        <pose relative_to='br_caster_rotation_link'>0 -0.012 -0.05 0 -0 0</pose>
        <parent>br_caster_rotation_link</parent>
        <child>br_caster_2_wheel_link</child>
        <axis>
          <xyz>0 1 0</xyz>
          <limit>
            <lower>-1e+16</lower>
            <upper>1e+16</upper>
          </limit>
          <dynamics>
            <spring_reference>0</spring_reference>
            <spring_stiffness>0</spring_stiffness>
          </dynamics>
        </axis>
      </joint>
      <link name='br_caster_2_wheel_link'>
        <pose relative_to='br_caster_wheel_2_joint'>0 0 0 0 -0 0</pose>
        <inertial>
          <pose>0 0 0 1.5708 -0 0</pose>
          <mass>0.5</mass>
          <inertia>
            <ixx>0.000216667</ixx>
            <ixy>0</ixy>
            <ixz>0</ixz>
            <iyy>0.000216667</iyy>
            <iyz>0</iyz>
            <izz>0.0004</izz>
          </inertia>
        </inertial>
        <collision name='br_caster_2_wheel_link_collision'>
          <pose>0 0 0 1.5708 -0 0</pose>
          <geometry>
            <cylinder>
              <length>0.02</length>
              <radius>0.04</radius>
            </cylinder>
          </geometry>
          <surface>
            <contact>
              <ode>
                <kp>1e+07</kp>
                <kd>1</kd>
                <min_depth>0.01</min_depth>
              </ode>
            </contact>
            <friction>
              <ode>
                <mu>0.1</mu>
                <mu2>0.1</mu2>
              </ode>
              <torsional>
                <ode/>
              </torsional>
            </friction>
            <bounce/>
          </surface>
          <max_contacts>10</max_contacts>
        </collision>
        <visual name='br_caster_2_wheel_link_visual'>
          <pose>0 0 0 1.5708 -0 0</pose>
          <geometry>
            <cylinder>
              <length>0.02</length>
              <radius>0.04</radius>
            </cylinder>
          </geometry>
          <material>
            <script>
              <name>Gazebo/FlatBlack</name>
              <uri>file://media/materials/scripts/gazebo.material</uri>
            </script>
          </material>
        </visual>
        <self_collide>0</self_collide>
        <enable_wind>0</enable_wind>
        <kinematic>0</kinematic>
      </link>
      <joint name='fl_caster_rotation_joint' type='revolute'>
        <pose relative_to='base_footprint'>0.4 0.247 0.0875 0 -0 0</pose>
        <parent>base_footprint</parent>
        <child>fl_caster_rotation_link</child>
        <axis>
          <xyz>0 0 1</xyz>
          <limit>
            <lower>-1e+16</lower>
            <upper>1e+16</upper>
          </limit>
          <dynamics>
            <damping>0.01</damping>
            <friction>0</friction>
            <spring_reference>0</spring_reference>
            <spring_stiffness>0</spring_stiffness>
          </dynamics>
        </axis>
      </joint>
      <link name='fl_caster_rotation_link'>
        <pose relative_to='fl_caster_rotation_joint'>0 0 0 0 -0 0</pose>
        <inertial>
          <pose>0 0 0 0 -0 0</pose>
          <mass>0.2</mass>
          <inertia>
            <ixx>7e-05</ixx>
            <ixy>0</ixy>
            <ixz>0</ixz>
            <iyy>3.9e-05</iyy>
            <iyz>0</iyz>
            <izz>9.24e-05</izz>
          </inertia>
        </inertial>
        <collision name='fl_caster_rotation_link_collision'>
          <pose>0 0 0 1.5708 -0 1.5708</pose>
          <geometry>
            <mesh>
              <scale>1 1 1</scale>
              <uri>/home/leanhchien/temas_work/temas_ws/src/amr_simulation/amr_description/meshes/caster_base.STL</uri>
            </mesh>
          </geometry>
          <surface>
            <contact>
              <ode/>
            </contact>
            <friction>
              <ode/>
              <torsional>
                <ode/>
              </torsional>
            </friction>
            <bounce/>
          </surface>
          <max_contacts>10</max_contacts>
        </collision>
        <visual name='fl_caster_rotation_link_visual'>
          <pose>0 0 0 1.5708 -0 1.5708</pose>
          <geometry>
            <mesh>
              <scale>1 1 1</scale>
              <uri>/home/leanhchien/temas_work/temas_ws/src/amr_simulation/amr_description/meshes/caster_base.STL</uri>
            </mesh>
          </geometry>
          <material>
            <script>
              <name>Gazebo/Grey</name>
              <uri>file://media/materials/scripts/gazebo.material</uri>
            </script>
          </material>
        </visual>
        <self_collide>0</self_collide>
        <enable_wind>0</enable_wind>
        <kinematic>0</kinematic>
      </link>
      <joint name='fl_caster_wheel_1_joint' type='revolute'>
        <pose relative_to='fl_caster_rotation_link'>0 0.012 -0.05 0 -0 0</pose>
        <parent>fl_caster_rotation_link</parent>
        <child>fl_caster_1_wheel_link</child>
        <axis>
          <xyz>0 1 0</xyz>
          <limit>
            <lower>-1e+16</lower>
            <upper>1e+16</upper>
          </limit>
          <dynamics>
            <spring_reference>0</spring_reference>
            <spring_stiffness>0</spring_stiffness>
          </dynamics>
        </axis>
      </joint>
      <link name='fl_caster_1_wheel_link'>
        <pose relative_to='fl_caster_wheel_1_joint'>0 0 0 0 -0 0</pose>
        <inertial>
          <pose>0 0 0 1.5708 -0 0</pose>
          <mass>0.5</mass>
          <inertia>
            <ixx>0.000216667</ixx>
            <ixy>0</ixy>
            <ixz>0</ixz>
            <iyy>0.000216667</iyy>
            <iyz>0</iyz>
            <izz>0.0004</izz>
          </inertia>
        </inertial>
        <collision name='fl_caster_1_wheel_link_collision'>
          <pose>0 0 0 1.5708 -0 0</pose>
          <geometry>
            <cylinder>
              <length>0.02</length>
              <radius>0.04</radius>
            </cylinder>
          </geometry>
          <surface>
            <contact>
              <ode>
                <kp>1e+07</kp>
                <kd>1</kd>
                <min_depth>0.01</min_depth>
              </ode>
            </contact>
            <friction>
              <ode>
                <mu>0.1</mu>
                <mu2>0.1</mu2>
              </ode>
              <torsional>
                <ode/>
              </torsional>
            </friction>
            <bounce/>
          </surface>
          <max_contacts>10</max_contacts>
        </collision>
        <visual name='fl_caster_1_wheel_link_visual'>
          <pose>0 0 0 1.5708 -0 0</pose>
          <geometry>
            <cylinder>
              <length>0.02</length>
              <radius>0.04</radius>
            </cylinder>
          </geometry>
          <material>
            <script>
              <name>Gazebo/FlatBlack</name>
              <uri>file://media/materials/scripts/gazebo.material</uri>
            </script>
          </material>
        </visual>
        <self_collide>0</self_collide>
        <enable_wind>0</enable_wind>
        <kinematic>0</kinematic>
      </link>
      <joint name='fl_caster_wheel_2_joint' type='revolute'>
        <pose relative_to='fl_caster_rotation_link'>0 -0.012 -0.05 0 -0 0</pose>
        <parent>fl_caster_rotation_link</parent>
        <child>fl_caster_2_wheel_link</child>
        <axis>
          <xyz>0 1 0</xyz>
          <limit>
            <lower>-1e+16</lower>
            <upper>1e+16</upper>
          </limit>
          <dynamics>
            <spring_reference>0</spring_reference>
            <spring_stiffness>0</spring_stiffness>
          </dynamics>
        </axis>
      </joint>
      <link name='fl_caster_2_wheel_link'>
        <pose relative_to='fl_caster_wheel_2_joint'>0 0 0 0 -0 0</pose>
        <inertial>
          <pose>0 0 0 1.5708 -0 0</pose>
          <mass>0.5</mass>
          <inertia>
            <ixx>0.000216667</ixx>
            <ixy>0</ixy>
            <ixz>0</ixz>
            <iyy>0.000216667</iyy>
            <iyz>0</iyz>
            <izz>0.0004</izz>
          </inertia>
        </inertial>
        <collision name='fl_caster_2_wheel_link_collision'>
          <pose>0 0 0 1.5708 -0 0</pose>
          <geometry>
            <cylinder>
              <length>0.02</length>
              <radius>0.04</radius>
            </cylinder>
          </geometry>
          <surface>
            <contact>
              <ode>
                <kp>1e+07</kp>
                <kd>1</kd>
                <min_depth>0.01</min_depth>
              </ode>
            </contact>
            <friction>
              <ode>
                <mu>0.1</mu>
                <mu2>0.1</mu2>
              </ode>
              <torsional>
                <ode/>
              </torsional>
            </friction>
            <bounce/>
          </surface>
          <max_contacts>10</max_contacts>
        </collision>
        <visual name='fl_caster_2_wheel_link_visual'>
          <pose>0 0 0 1.5708 -0 0</pose>
          <geometry>
            <cylinder>
              <length>0.02</length>
              <radius>0.04</radius>
            </cylinder>
          </geometry>
          <material>
            <script>
              <name>Gazebo/FlatBlack</name>
              <uri>file://media/materials/scripts/gazebo.material</uri>
            </script>
          </material>
        </visual>
        <self_collide>0</self_collide>
        <enable_wind>0</enable_wind>
        <kinematic>0</kinematic>
      </link>
      <joint name='fr_caster_rotation_joint' type='revolute'>
        <pose relative_to='base_footprint'>0.4 -0.247 0.0875 0 -0 0</pose>
        <parent>base_footprint</parent>
        <child>fr_caster_rotation_link</child>
        <axis>
          <xyz>0 0 1</xyz>
          <limit>
            <lower>-1e+16</lower>
            <upper>1e+16</upper>
          </limit>
          <dynamics>
            <damping>0.01</damping>
            <friction>0</friction>
            <spring_reference>0</spring_reference>
            <spring_stiffness>0</spring_stiffness>
          </dynamics>
        </axis>
      </joint>
      <link name='fr_caster_rotation_link'>
        <pose relative_to='fr_caster_rotation_joint'>0 0 0 0 -0 0</pose>
        <inertial>
          <pose>0 0 0 0 -0 0</pose>
          <mass>0.2</mass>
          <inertia>
            <ixx>7e-05</ixx>
            <ixy>0</ixy>
            <ixz>0</ixz>
            <iyy>3.9e-05</iyy>
            <iyz>0</iyz>
            <izz>9.24e-05</izz>
          </inertia>
        </inertial>
        <collision name='fr_caster_rotation_link_collision'>
          <pose>0 0 0 1.5708 -0 1.5708</pose>
          <geometry>
            <mesh>
              <scale>1 1 1</scale>
              <uri>/home/leanhchien/temas_work/temas_ws/src/amr_simulation/amr_description/meshes/caster_base.STL</uri>
            </mesh>
          </geometry>
          <surface>
            <contact>
              <ode/>
            </contact>
            <friction>
              <ode/>
              <torsional>
                <ode/>
              </torsional>
            </friction>
            <bounce/>
          </surface>
          <max_contacts>10</max_contacts>
        </collision>
        <visual name='fr_caster_rotation_link_visual'>
          <pose>0 0 0 1.5708 -0 1.5708</pose>
          <geometry>
            <mesh>
              <scale>1 1 1</scale>
              <uri>/home/leanhchien/temas_work/temas_ws/src/amr_simulation/amr_description/meshes/caster_base.STL</uri>
            </mesh>
          </geometry>
          <material>
            <script>
              <name>Gazebo/Grey</name>
              <uri>file://media/materials/scripts/gazebo.material</uri>
            </script>
          </material>
        </visual>
        <self_collide>0</self_collide>
        <enable_wind>0</enable_wind>
        <kinematic>0</kinematic>
      </link>
      <joint name='fr_caster_wheel_1_joint' type='revolute'>
        <pose relative_to='fr_caster_rotation_link'>0 0.012 -0.05 0 -0 0</pose>
        <parent>fr_caster_rotation_link</parent>
        <child>fr_caster_1_wheel_link</child>
        <axis>
          <xyz>0 1 0</xyz>
          <limit>
            <lower>-1e+16</lower>
            <upper>1e+16</upper>
          </limit>
          <dynamics>
            <spring_reference>0</spring_reference>
            <spring_stiffness>0</spring_stiffness>
          </dynamics>
        </axis>
      </joint>
      <link name='fr_caster_1_wheel_link'>
        <pose relative_to='fr_caster_wheel_1_joint'>0 0 0 0 -0 0</pose>
        <inertial>
          <pose>0 0 0 1.5708 -0 0</pose>
          <mass>0.5</mass>
          <inertia>
            <ixx>0.000216667</ixx>
            <ixy>0</ixy>
            <ixz>0</ixz>
            <iyy>0.000216667</iyy>
            <iyz>0</iyz>
            <izz>0.0004</izz>
          </inertia>
        </inertial>
        <collision name='fr_caster_1_wheel_link_collision'>
          <pose>0 0 0 1.5708 -0 0</pose>
          <geometry>
            <cylinder>
              <length>0.02</length>
              <radius>0.04</radius>
            </cylinder>
          </geometry>
          <surface>
            <contact>
              <ode>
                <kp>1e+07</kp>
                <kd>1</kd>
                <min_depth>0.01</min_depth>
              </ode>
            </contact>
            <friction>
              <ode>
                <mu>0.1</mu>
                <mu2>0.1</mu2>
              </ode>
              <torsional>
                <ode/>
              </torsional>
            </friction>
            <bounce/>
          </surface>
          <max_contacts>10</max_contacts>
        </collision>
        <visual name='fr_caster_1_wheel_link_visual'>
          <pose>0 0 0 1.5708 -0 0</pose>
          <geometry>
            <cylinder>
              <length>0.02</length>
              <radius>0.04</radius>
            </cylinder>
          </geometry>
          <material>
            <script>
              <name>Gazebo/FlatBlack</name>
              <uri>file://media/materials/scripts/gazebo.material</uri>
            </script>
          </material>
        </visual>
        <self_collide>0</self_collide>
        <enable_wind>0</enable_wind>
        <kinematic>0</kinematic>
      </link>
      <joint name='fr_caster_wheel_2_joint' type='revolute'>
        <pose relative_to='fr_caster_rotation_link'>0 -0.012 -0.05 0 -0 0</pose>
        <parent>fr_caster_rotation_link</parent>
        <child>fr_caster_2_wheel_link</child>
        <axis>
          <xyz>0 1 0</xyz>
          <limit>
            <lower>-1e+16</lower>
            <upper>1e+16</upper>
          </limit>
          <dynamics>
            <spring_reference>0</spring_reference>
            <spring_stiffness>0</spring_stiffness>
          </dynamics>
        </axis>
      </joint>
      <link name='fr_caster_2_wheel_link'>
        <pose relative_to='fr_caster_wheel_2_joint'>0 0 0 0 -0 0</pose>
        <inertial>
          <pose>0 0 0 1.5708 -0 0</pose>
          <mass>0.5</mass>
          <inertia>
            <ixx>0.000216667</ixx>
            <ixy>0</ixy>
            <ixz>0</ixz>
            <iyy>0.000216667</iyy>
            <iyz>0</iyz>
            <izz>0.0004</izz>
          </inertia>
        </inertial>
        <collision name='fr_caster_2_wheel_link_collision'>
          <pose>0 0 0 1.5708 -0 0</pose>
          <geometry>
            <cylinder>
              <length>0.02</length>
              <radius>0.04</radius>
            </cylinder>
          </geometry>
          <surface>
            <contact>
              <ode>
                <kp>1e+07</kp>
                <kd>1</kd>
                <min_depth>0.01</min_depth>
              </ode>
            </contact>
            <friction>
              <ode>
                <mu>0.1</mu>
                <mu2>0.1</mu2>
              </ode>
              <torsional>
                <ode/>
              </torsional>
            </friction>
            <bounce/>
          </surface>
          <max_contacts>10</max_contacts>
        </collision>
        <visual name='fr_caster_2_wheel_link_visual'>
          <pose>0 0 0 1.5708 -0 0</pose>
          <geometry>
            <cylinder>
              <length>0.02</length>
              <radius>0.04</radius>
            </cylinder>
          </geometry>
          <material>
            <script>
              <name>Gazebo/FlatBlack</name>
              <uri>file://media/materials/scripts/gazebo.material</uri>
            </script>
          </material>
        </visual>
        <self_collide>0</self_collide>
        <enable_wind>0</enable_wind>
        <kinematic>0</kinematic>
      </link>
      <joint name='left_wheel_joint' type='revolute'>
        <pose relative_to='base_footprint'>0 0.267 0.09 0 -0 0</pose>
        <parent>base_footprint</parent>
        <child>left_wheel_link</child>
        <axis>
          <xyz>0 1 0</xyz>
          <limit>
            <effort>100</effort>
            <velocity>20</velocity>
            <lower>-1e+16</lower>
            <upper>1e+16</upper>
          </limit>
          <dynamics>
            <spring_reference>0</spring_reference>
            <spring_stiffness>0</spring_stiffness>
          </dynamics>
        </axis>
      </joint>
      <link name='left_wheel_link'>
        <pose relative_to='left_wheel_joint'>0 0 0 0 -0 0</pose>
        <inertial>
          <pose>0 0 0 1.5708 -0 0</pose>
          <mass>1</mass>
          <inertia>
            <ixx>0.00215833</ixx>
            <ixy>0</ixy>
            <ixz>0</ixz>
            <iyy>0.00215833</iyy>
            <iyz>0</iyz>
            <izz>0.00405</izz>
          </inertia>
        </inertial>
        <collision name='left_wheel_link_collision'>
          <pose>0 0 0 1.5708 -0 0</pose>
          <geometry>
            <cylinder>
              <length>0.04</length>
              <radius>0.09</radius>
            </cylinder>
          </geometry>
          <surface>
            <contact>
              <ode>
                <kp>1e+07</kp>
                <kd>1</kd>
                <min_depth>0.01</min_depth>
              </ode>
            </contact>
            <friction>
              <ode>
                <mu>200</mu>
                <mu2>200</mu2>
              </ode>
              <torsional>
                <ode/>
              </torsional>
            </friction>
            <bounce/>
          </surface>
          <max_contacts>10</max_contacts>
        </collision>
        <visual name='left_wheel_link_visual'>
          <pose>0 0 0 1.5708 -0 0</pose>
          <geometry>
            <cylinder>
              <length>0.04</length>
              <radius>0.09</radius>
            </cylinder>
          </geometry>
          <material>
            <script>
              <name>Gazebo/FlatBlack</name>
              <uri>file://media/materials/scripts/gazebo.material</uri>
            </script>
          </material>
        </visual>
        <self_collide>0</self_collide>
        <enable_wind>0</enable_wind>
        <kinematic>0</kinematic>
      </link>
      <joint name='right_wheel_joint' type='revolute'>
        <pose relative_to='base_footprint'>0 -0.267 0.09 0 -0 0</pose>
        <parent>base_footprint</parent>
        <child>right_wheel_link</child>
        <axis>
          <xyz>0 1 0</xyz>
          <limit>
            <effort>100</effort>
            <velocity>20</velocity>
            <lower>-1e+16</lower>
            <upper>1e+16</upper>
          </limit>
          <dynamics>
            <spring_reference>0</spring_reference>
            <spring_stiffness>0</spring_stiffness>
          </dynamics>
        </axis>
      </joint>
      <link name='right_wheel_link'>
        <pose relative_to='right_wheel_joint'>0 0 0 0 -0 0</pose>
        <inertial>
          <pose>0 0 0 1.5708 -0 0</pose>
          <mass>1</mass>
          <inertia>
            <ixx>0.00215833</ixx>
            <ixy>0</ixy>
            <ixz>0</ixz>
            <iyy>0.00215833</iyy>
            <iyz>0</iyz>
            <izz>0.00405</izz>
          </inertia>
        </inertial>
        <collision name='right_wheel_link_collision'>
          <pose>0 0 0 1.5708 -0 0</pose>
          <geometry>
            <cylinder>
              <length>0.04</length>
              <radius>0.09</radius>
            </cylinder>
          </geometry>
          <surface>
            <contact>
              <ode>
                <kp>1e+07</kp>
                <kd>1</kd>
                <min_depth>0.01</min_depth>
              </ode>
            </contact>
            <friction>
              <ode>
                <mu>200</mu>
                <mu2>200</mu2>
              </ode>
              <torsional>
                <ode/>
              </torsional>
            </friction>
            <bounce/>
          </surface>
          <max_contacts>10</max_contacts>
        </collision>
        <visual name='right_wheel_link_visual'>
          <pose>0 0 0 1.5708 -0 0</pose>
          <geometry>
            <cylinder>
              <length>0.04</length>
              <radius>0.09</radius>
            </cylinder>
          </geometry>
          <material>
            <script>
              <name>Gazebo/FlatBlack</name>
              <uri>file://media/materials/scripts/gazebo.material</uri>
            </script>
          </material>
        </visual>
        <self_collide>0</self_collide>
        <enable_wind>0</enable_wind>
        <kinematic>0</kinematic>
      </link>
      <plugin name='imu_plugin' filename='libhector_gazebo_ros_imu.so'>
        <updateRate>50.0</updateRate>
        <frameId>imu_frame</frameId>
        <topicName>imu_data</topicName>
        <accelDrift>0.0 0.0 0.0</accelDrift>
        <accelGaussianNoise>0.007071067811865475 0.01 0.011401754250991379</accelGaussianNoise>
        <rateDrift>0.0 0.0 0.0</rateDrift>
        <rateGaussianNoise>0.00282842712474619 0.00282842712474619 0.0005477225575051661</rateGaussianNoise>
        <yawDrift>0.0</yawDrift>
        <yawGaussianNoise>0.31622776601683794</yawGaussianNoise>
        <robotNamespace>/</robotNamespace>
        <bodyName>base_footprint</bodyName>
        <xyzOffset>0 0 0.123</xyzOffset>
        <rpyOffset>0 -0 0</rpyOffset>
        <ignition::corrected_offsets>1</ignition::corrected_offsets>
      </plugin>
      <plugin name='p3d_base_controller' filename='libgazebo_ros_p3d.so'>
        <alwaysOn>1</alwaysOn>
        <updateRate>50.0</updateRate>
        <bodyName>base_footprint</bodyName>
        <topicName>base_pose_ground_truth</topicName>
        <gaussianNoise>0.01</gaussianNoise>
        <frameName>map</frameName>
        <xyzOffsets>0 0 0</xyzOffsets>
        <rpyOffsets>0 0 0</rpyOffsets>
        <robotNamespace>/</robotNamespace>
      </plugin>
      <plugin name='gazebo_ros_control' filename='libgazebo_ros_control.so'>
        <controlPeriod>0.001</controlPeriod>
        <legacyModeNS>0</legacyModeNS>
        <robotNamespace>/</robotNamespace>
      </plugin>
      <frame name='base_link_to_back_laser_joint' attached_to='base_link'>
        <pose>-0.4 -0 0.086 0 -0 3.14159</pose>
      </frame>
      <frame name='back_laser_link' attached_to='base_link_to_back_laser_joint'/>
      <frame name='base_link_to_front_laser_joint' attached_to='base_link'>
        <pose>0.4 0 0.086 0 -0 0</pose>
      </frame>
      <frame name='front_laser_link' attached_to='base_link_to_front_laser_joint'/>
      <frame name='imu_link_to_imu_frame_joint' attached_to='imu_link'>
        <pose>0 0 0 0 -0 0</pose>
      </frame>
      <frame name='imu_frame' attached_to='imu_link_to_imu_frame_joint'/>
      <frame name='base_link_to_imu_joint' attached_to='base_link'>
        <pose>0 0 0.123 0 -0 0</pose>
      </frame>
      <frame name='imu_link' attached_to='base_link_to_imu_joint'/>
      <frame name='base_joint' attached_to='base_footprint'>
        <pose>0 0 0 0 -0 0</pose>
      </frame>
      <frame name='base_link' attached_to='base_joint'/>
      <pose>3.6 0 0 0 -0 0</pose>
    </model>
  </world>
</sdf>
